Here is the list of inputs:
OPTIONS jobs 2
OPTIONS queues 1
OPTIONS allotments for queue  0 is   1
OPTIONS quantum length for queue  0 is   1
OPTIONS boost 0
OPTIONS ioTime 5
OPTIONS stayAfterIO False
OPTIONS iobump False


For each job, three defining characteristics are given:
  startTime : at what time does the job enter the system
  runTime   : the total CPU time needed by the job to finish
  ioFreq    : every ioFreq time units, the job issues an I/O
              (the I/O takes ioTime units to complete)

Job List:
  Job  0: startTime   0 - runTime  20 - ioFreq   0
  Job  1: startTime   0 - runTime  20 - ioFreq   0


Execution Trace:

[ time 0 ] JOB BEGINS by JOB 0
[ time 0 ] JOB BEGINS by JOB 1
[ time 0 ] Run JOB 0 at PRIORITY 0 [ TICKS 0 ALLOT 1 TIME 19 (of 20) ]
[ time 1 ] Run JOB 1 at PRIORITY 0 [ TICKS 0 ALLOT 1 TIME 19 (of 20) ]
[ time 2 ] Run JOB 0 at PRIORITY 0 [ TICKS 0 ALLOT 1 TIME 18 (of 20) ]
[ time 3 ] Run JOB 1 at PRIORITY 0 [ TICKS 0 ALLOT 1 TIME 18 (of 20) ]
[ time 4 ] Run JOB 0 at PRIORITY 0 [ TICKS 0 ALLOT 1 TIME 17 (of 20) ]
[ time 5 ] Run JOB 1 at PRIORITY 0 [ TICKS 0 ALLOT 1 TIME 17 (of 20) ]
[ time 6 ] Run JOB 0 at PRIORITY 0 [ TICKS 0 ALLOT 1 TIME 16 (of 20) ]
[ time 7 ] Run JOB 1 at PRIORITY 0 [ TICKS 0 ALLOT 1 TIME 16 (of 20) ]
[ time 8 ] Run JOB 0 at PRIORITY 0 [ TICKS 0 ALLOT 1 TIME 15 (of 20) ]
[ time 9 ] Run JOB 1 at PRIORITY 0 [ TICKS 0 ALLOT 1 TIME 15 (of 20) ]
[ time 10 ] Run JOB 0 at PRIORITY 0 [ TICKS 0 ALLOT 1 TIME 14 (of 20) ]
[ time 11 ] Run JOB 1 at PRIORITY 0 [ TICKS 0 ALLOT 1 TIME 14 (of 20) ]
[ time 12 ] Run JOB 0 at PRIORITY 0 [ TICKS 0 ALLOT 1 TIME 13 (of 20) ]
[ time 13 ] Run JOB 1 at PRIORITY 0 [ TICKS 0 ALLOT 1 TIME 13 (of 20) ]
[ time 14 ] Run JOB 0 at PRIORITY 0 [ TICKS 0 ALLOT 1 TIME 12 (of 20) ]
[ time 15 ] Run JOB 1 at PRIORITY 0 [ TICKS 0 ALLOT 1 TIME 12 (of 20) ]
[ time 16 ] Run JOB 0 at PRIORITY 0 [ TICKS 0 ALLOT 1 TIME 11 (of 20) ]
[ time 17 ] Run JOB 1 at PRIORITY 0 [ TICKS 0 ALLOT 1 TIME 11 (of 20) ]
[ time 18 ] Run JOB 0 at PRIORITY 0 [ TICKS 0 ALLOT 1 TIME 10 (of 20) ]
[ time 19 ] Run JOB 1 at PRIORITY 0 [ TICKS 0 ALLOT 1 TIME 10 (of 20) ]
[ time 20 ] Run JOB 0 at PRIORITY 0 [ TICKS 0 ALLOT 1 TIME 9 (of 20) ]
[ time 21 ] Run JOB 1 at PRIORITY 0 [ TICKS 0 ALLOT 1 TIME 9 (of 20) ]
[ time 22 ] Run JOB 0 at PRIORITY 0 [ TICKS 0 ALLOT 1 TIME 8 (of 20) ]
[ time 23 ] Run JOB 1 at PRIORITY 0 [ TICKS 0 ALLOT 1 TIME 8 (of 20) ]
[ time 24 ] Run JOB 0 at PRIORITY 0 [ TICKS 0 ALLOT 1 TIME 7 (of 20) ]
[ time 25 ] Run JOB 1 at PRIORITY 0 [ TICKS 0 ALLOT 1 TIME 7 (of 20) ]
[ time 26 ] Run JOB 0 at PRIORITY 0 [ TICKS 0 ALLOT 1 TIME 6 (of 20) ]
[ time 27 ] Run JOB 1 at PRIORITY 0 [ TICKS 0 ALLOT 1 TIME 6 (of 20) ]
[ time 28 ] Run JOB 0 at PRIORITY 0 [ TICKS 0 ALLOT 1 TIME 5 (of 20) ]
[ time 29 ] Run JOB 1 at PRIORITY 0 [ TICKS 0 ALLOT 1 TIME 5 (of 20) ]
[ time 30 ] Run JOB 0 at PRIORITY 0 [ TICKS 0 ALLOT 1 TIME 4 (of 20) ]
[ time 31 ] Run JOB 1 at PRIORITY 0 [ TICKS 0 ALLOT 1 TIME 4 (of 20) ]
[ time 32 ] Run JOB 0 at PRIORITY 0 [ TICKS 0 ALLOT 1 TIME 3 (of 20) ]
[ time 33 ] Run JOB 1 at PRIORITY 0 [ TICKS 0 ALLOT 1 TIME 3 (of 20) ]
[ time 34 ] Run JOB 0 at PRIORITY 0 [ TICKS 0 ALLOT 1 TIME 2 (of 20) ]
[ time 35 ] Run JOB 1 at PRIORITY 0 [ TICKS 0 ALLOT 1 TIME 2 (of 20) ]
[ time 36 ] Run JOB 0 at PRIORITY 0 [ TICKS 0 ALLOT 1 TIME 1 (of 20) ]
[ time 37 ] Run JOB 1 at PRIORITY 0 [ TICKS 0 ALLOT 1 TIME 1 (of 20) ]
[ time 38 ] Run JOB 0 at PRIORITY 0 [ TICKS 0 ALLOT 1 TIME 0 (of 20) ]
[ time 39 ] FINISHED JOB 0
[ time 39 ] Run JOB 1 at PRIORITY 0 [ TICKS 0 ALLOT 1 TIME 0 (of 20) ]
[ time 40 ] FINISHED JOB 1

Final statistics:
  Job  0: startTime   0 - response   0 - turnaround  39
  Job  1: startTime   0 - response   1 - turnaround  40

  Avg  1: startTime n/a - response 0.50 - turnaround 39.50


